<?xml version="1.0" encoding="utf-8"?>
<!-- =================================================================================== -->
<!-- |    This document was autogenerated by xacro from model_xacro.xacro              | -->
<!-- |    EDITING THIS FILE BY HAND IS NOT RECOMMENDED                                 | -->
<!-- =================================================================================== -->
<robot name="robot">
  <!--==============================-->
  <!-- chassis du robot-->
  <link name="base_link">
    <visual>
      <geometry>
        <box size="0.28 0.15 0.15"/>
      </geometry>
    </visual>
    <collision>
      <geometry>
        <box size="0.28 0.15 0.15"/>
      </geometry>
    </collision>
  </link>
  <!-- ============================== -->
  <!-- inertie du chassis du robot-->
  <link name="base_inertie">
    <inertial>
      <mass value="5"/>
      <inertia ixx="0.075" ixy="0.0525" ixz="0.0525" iyx="0.0" iyy="0.168166666667" iyz="0.028125" izx="0.0" izy="0.0" izz="0.168166666667"/>
    </inertial>
  </link>
  <!-- liaison cinematique-->
  <joint name="joint_base_inertie" type="fixed">
    <parent link="base_link"/>
    <child link="base_inertie"/>
  </joint>
  <!-- ============================== -->
  <!-- support camera -->
  <link name="Support_Cam">
    <visual>
      <origin rpy="0.0 0.0 0.0" xyz="0.01 0.0 0.0"/>
      <geometry>
        <box size="0.02 0.05 0.05"/>
      </geometry>
    </visual>
    <collision>
      <origin rpy="0.0 0.0 0.0" xyz="0.01 0.0 0.0"/>
      <geometry>
        <box size="0.02 0.05 0.05"/>
      </geometry>
    </collision>
  </link>
  <!-- liaison cinematique-->
  <joint name="joint_Support_Cam" type="fixed">
    <origin rpy="0.0 0.0 0.0" xyz="0.14 0.0 0.02"/>
    <parent link="base_link"/>
    <child link="Support_Cam"/>
  </joint>
  <!-- ============================== -->
  <!-- Antenne 1 du robot -->
  <link name="antenne1">
    <visual>
      <origin rpy="0.0 0.0 0.0" xyz="0.0 0.0 0.05"/>
      <geometry>
        <cylinder length="0.1" radius="0.01"/>
      </geometry>
    </visual>
    <collision>
      <origin rpy="0.0 0.0 0.0" xyz="0.0 0.0 0.05"/>
      <geometry>
        <cylinder length="0.1" radius="0.01"/>
      </geometry>
    </collision>
  </link>
  <!-- liaison cinematique-->
  <joint name="joint_antenne1" type="fixed">
    <origin rpy="0.0 0.0 0.0" xyz="-0.10 0.03 0.075"/>
    <parent link="base_link"/>
    <child link="antenne1"/>
  </joint>
  <!-- ============================== -->
  <!-- Antenne 2 du robot -->
  <link name="antenne2">
    <visual>
      <origin rpy="0.0 0.0 0.0" xyz="0.0 0.0 0.05"/>
      <geometry>
        <cylinder length="0.1" radius="0.01"/>
      </geometry>
    </visual>
    <collision>
      <origin rpy="0.0 0.0 0.0" xyz="0.0 0.0 0.05"/>
      <geometry>
        <cylinder length="0.1" radius="0.01"/>
      </geometry>
    </collision>
  </link>
  <!-- liaison cinematique-->
  <joint name="joint_antenne2" type="fixed">
    <origin rpy="0.0 0.0 0.0" xyz="-0.10 -0.03 0.075"/>
    <parent link="base_link"/>
    <child link="antenne2"/>
  </joint>
  <!-- ============================== -->
  <!-- roue avant droite du robot -->
  <link name="Roue_AD">
    <visual>
      <origin rpy="1.57 0.0 0.0" xyz="0.0 0.035 0.0"/>
      <geometry>
        <cylinder length="0.07" radius="0.04"/>
      </geometry>
    </visual>
    <collision>
      <origin rpy="1.57 0.0 0.0" xyz="0.0 0.035 0.0"/>
      <geometry>
        <cylinder length="0.07" radius="0.04"/>
      </geometry>
    </collision>
    <inertial>
      <mass value="1"/>
      <inertia ixx="0.000808333333333" ixy="0.0" ixz="0.0" iyx="0.0" iyy="0.000808333333333" iyz="0.0" izx="0.0" izy="0.0" izz="0.0008"/>
    </inertial>
  </link>
  <!-- liaison cinematique-->
  <joint name="joint_Roue_AD" type="continuous">
    <origin rpy="0.0 0.0 0.0" xyz="0.10 0.075 -0.06"/>
    <parent link="base_link"/>
    <child link="Roue_AD"/>
    <axis xyz="0.0 1 0.0"/>
  </joint>
  <!-- ============================== -->
  <!-- roue arriere droite du robot -->
  <link name="Roue_DD">
    <visual>
      <origin rpy="1.57 0.0 0.0" xyz="0.0 0.035 0.0"/>
      <geometry>
        <cylinder length="0.07" radius="0.04"/>
      </geometry>
    </visual>
    <collision>
      <origin rpy="1.57 0.0 0.0" xyz="0.0 0.035 0.0"/>
      <geometry>
        <cylinder length="0.07" radius="0.04"/>
      </geometry>
    </collision>
    <inertial>
      <mass value="1"/>
      <inertia ixx="0.000808333333333" ixy="0.0" ixz="0.0" iyx="0.0" iyy="0.000808333333333" iyz="0.0" izx="0.0" izy="0.0" izz="0.0008"/>
    </inertial>
  </link>
  <!-- liaison cinematique-->
  <joint name="joint_Roue_DD" type="continuous">
    <origin rpy="0.0 0.0 0.0" xyz="-0.10 0.075 -0.06"/>
    <parent link="base_link"/>
    <child link="Roue_DD"/>
    <axis xyz="0.0 1 0.0"/>
  </joint>
  <!-- ============================== -->
  <!-- roue avant gauche du robot -->
  <link name="Roue_AG">
    <visual>
      <origin rpy="1.57 0.0 0.0" xyz="0.0 -0.035 0.0"/>
      <geometry>
        <cylinder length="0.07" radius="0.04"/>
      </geometry>
    </visual>
    <collision>
      <origin rpy="1.57 0.0 0.0" xyz="0.0 -0.035 0.0"/>
      <geometry>
        <cylinder length="0.07" radius="0.04"/>
      </geometry>
    </collision>
    <inertial>
      <mass value="1"/>
      <inertia ixx="0.000808333333333" ixy="0.0" ixz="0.0" iyx="0.0" iyy="0.000808333333333" iyz="0.0" izx="0.0" izy="0.0" izz="0.0008"/>
    </inertial>
  </link>
  <!-- liaison cinematique-->
  <joint name="joint_Roue_AG" type="continuous">
    <origin rpy="0.0 0.0 0.0" xyz="0.10 -0.075 -0.06"/>
    <parent link="base_link"/>
    <child link="Roue_AG"/>
    <axis xyz="0.0 1 0.0"/>
  </joint>
  <!-- ============================== -->
  <!-- roue avant gauche du robot -->
  <link name="Roue_DG">
    <visual>
      <origin rpy="1.57 0.0 0.0" xyz="0.0 -0.035 0.0"/>
      <geometry>
        <cylinder length="0.07" radius="0.04"/>
      </geometry>
    </visual>
    <collision>
      <origin rpy="1.57 0.0 0.0" xyz="0.0 -0.035 0.0"/>
      <geometry>
        <cylinder length="0.07" radius="0.04"/>
      </geometry>
    </collision>
    <inertial>
      <mass value="1"/>
      <inertia ixx="0.000808333333333" ixy="0.0" ixz="0.0" iyx="0.0" iyy="0.000808333333333" iyz="0.0" izx="0.0" izy="0.0" izz="0.0008"/>
    </inertial>
  </link>
  <!-- liaison cinematique-->
  <joint name="joint_Roue_DG" type="continuous">
    <origin rpy="0.0 0.0 0.0" xyz="-0.10 -0.075 -0.06"/>
    <parent link="base_link"/>
    <child link="Roue_DG"/>
    <axis xyz="0.0 1 0.0"/>
  </joint>
  <!-- ============================== -->
</robot>

